<?xml version="1.0"?>
<robot xmlns:xacro="http://ros.org/wiki/xacro">
  <xacro:include filename="$(find abb_resources)/urdf/common_materials.xacro"/>

  <xacro:macro name="abb_irbt4004" params="prefix">

    <!-- link zero-->
<!--    <link name="${prefix}world"/>-->

    <!-- link list -->
    <link name="${prefix}base_link"> <!--track_start-->
      <visual>
        <origin xyz="0 0 0" rpy="0 0 0"/>
        <geometry>
          <mesh filename="package://abb_irbt4004_support/meshes/irbt4004/visual/Track_Start.stl"/>
        </geometry>
        <xacro:material_abb_orange />
      </visual>
      <collision>
        <origin xyz="0 0 0" rpy="0 0 0"/>
        <geometry>
          <mesh filename="package://abb_irbt4004_support/meshes/irbt4004/collision/Track_Start.stl"/>
        </geometry>
        <xacro:material_abb_orange />
      </collision>
    </link>

    <link name="${prefix}track_mid_1">
      <visual>
        <origin xyz="0 0 0" rpy="0 0 0"/>
        <geometry>
          <mesh filename="package://abb_irbt4004_support/meshes/irbt4004/visual/Track_Mid.stl"/>
        </geometry>
        <xacro:material_abb_orange />
      </visual>
      <collision>
        <origin xyz="0 0 0" rpy="0 0 0"/>
        <geometry>
          <mesh filename="package://abb_irbt4004_support/meshes/irbt4004/collision/Track_Mid.stl"/>
        </geometry>
        <xacro:material_abb_orange />
      </collision>
    </link>

    <link name="${prefix}track_mid_2">
      <visual>
        <origin xyz="0 0 0" rpy="0 0 0"/>
        <geometry>
          <mesh filename="package://abb_irbt4004_support/meshes/irbt4004/visual/Track_Mid.stl"/>
        </geometry>
        <xacro:material_abb_orange />
      </visual>
      <collision>
        <origin xyz="0 0 0" rpy="0 0 0"/>
        <geometry>
          <mesh filename="package://abb_irbt4004_support/meshes/irbt4004/collision/Track_Mid.stl"/>
        </geometry>
        <xacro:material_abb_orange />
      </collision>
    </link>

    <link name="${prefix}track_mid_3">
      <visual>
        <origin xyz="0 0 0" rpy="0 0 0"/>
        <geometry>
          <mesh filename="package://abb_irbt4004_support/meshes/irbt4004/visual/Track_Mid.stl"/>
        </geometry>
        <xacro:material_abb_orange />
      </visual>
      <collision>
        <origin xyz="0 0 0" rpy="0 0 0"/>
        <geometry>
          <mesh filename="package://abb_irbt4004_support/meshes/irbt4004/collision/Track_Mid.stl"/>
        </geometry>
        <xacro:material_abb_orange />
      </collision>
    </link>

    <!-- no end section
    <link name="${prefix}track_end">
      <visual>
        <origin xyz="0 0 0" rpy="0 0 0"/>
        <geometry>
          <mesh filename="package://abb_irbt4004_support/meshes/irb4400/visual/Track_End.stl"/>
        </geometry>
        <xacro:material_abb_orange />
      </visual>
      <collision>
        <origin xyz="0 0 0" rpy="0 0 0"/>
        <geometry>
          <mesh filename="package://abb_irbt4004_support/meshes/irb4400/collision/Track_End.stl"/>
        </geometry>
        <xacro:material_abb_orange />
      </collision>
    </link>
    -->

    <link name="${prefix}carriage">
      <visual>
        <origin xyz="0 0 0" rpy="0 0 0"/>
        <geometry>
          <mesh filename="package://abb_irbt4004_support/meshes/irbt4004/visual/Carriage_left.stl"/>
        </geometry>
        <xacro:material_abb_dark_gray />
      </visual>
      <collision>
        <origin xyz="0 0 0" rpy="0 0 0"/>
        <geometry>
          <mesh filename="package://abb_irbt4004_support/meshes/irbt4004/collision/Carriage_left.stl"/>
        </geometry>
        <xacro:material_abb_dark_gray />
      </collision>
    </link>
    <!-- end of link list -->

    <!-- joint list -->
    <joint name="${prefix}fixed_track_mid_1" type="fixed">
      <parent link="${prefix}base_link"/>
      <child link="${prefix}track_mid_1"/>
      <origin xyz="0.000 0.000 0.000" rpy="0 0 0"/>
    </joint>

    <joint name="${prefix}fixed_track_mid_2" type="fixed">
      <parent link="${prefix}track_mid_1"/>
      <child link="${prefix}track_mid_2"/>
      <origin xyz="1.000 0.000 0.000" rpy="0 0 0"/>
    </joint>

    <joint name="${prefix}fixed_track_mid_3" type="fixed">
      <parent link="${prefix}track_mid_2"/>
      <child link="${prefix}track_mid_3"/>
      <origin xyz="1.000 0.000 0.000" rpy="0 0 0"/>
    </joint>

    <!-- no end section
    <joint name="${prefix}fixed_track_end" type="fixed">
      <parent link="${prefix}track_mid_3"/>
      <child link="${prefix}track_end"/>
      <origin xyz="1.000 0.000 0.000" rpy="0 0 0"/>
    </joint>
    -->

    <joint name="${prefix}joint_carriage" type="prismatic">
      <parent link="${prefix}base_link"/>
      <child link="${prefix}carriage"/>
      <axis xyz="1 0 0"/>
      <limit effort="0" lower="0.000" upper="3.700" velocity="2.000"/> <!-- Product specification - IRBT 4004/6004/7004 -->
    </joint>

    <!-- offset to center base plate for robot mounting position
    <joint name="${prefix}fixed_base_link" type="fixed">
      <parent link="${prefix}carriage"/>
      <child link="${prefix}base_link"/>
      <origin xyz="0.3955 0.560 0.3745" rpy="0 0 1.57079632"/>
    </joint>-->
    <!-- end of joint list -->


<!-- ROS base_link to ABB World Coordinates transform -->
    <link name="${prefix}base" />
    <joint name="${prefix}base_link-base" type="fixed">
      <origin xyz="0 0 0" rpy="0 0 0"/>
      <parent link="${prefix}base_link"/>
      <child link="${prefix}base"/>
    </joint>

  </xacro:macro>
</robot>
