<?xml version="1.0" ?>
<!-- =================================================================================== -->
<!-- |    This document was autogenerated by xacro from irbt4004.xacro                 | -->
<!-- |    EDITING THIS FILE BY HAND IS NOT RECOMMENDED                                 | -->
<!-- =================================================================================== -->
<robot name="abb_irbt4004" xmlns:xacro="http://ros.org/wiki/xacro">
  <!-- Conversion were obtained from http://www.e-paint.co.uk/Lab_values.asp
       unless otherwise stated. -->
  <!-- link zero-->
  <!--    <link name="${prefix}world"/>-->
  <!-- link list -->
  <link name="base_link">
    <!--track_start-->
    <visual>
      <origin rpy="0 0 0" xyz="0 0 0"/>
      <geometry>
        <mesh filename="package://abb_irbt4004/meshes/irbt4004/visual/Track_Start.stl"/>
      </geometry>
      <material name="">
        <color rgba="0.7372549 0.3490196 0.1607843 1"/>
      </material>
    </visual>
    <collision>
      <origin rpy="0 0 0" xyz="0 0 0"/>
      <geometry>
        <mesh filename="package://abb_irbt4004/meshes/irbt4004/collision/Track_Start.stl"/>
      </geometry>
      <material name="">
        <color rgba="0.7372549 0.3490196 0.1607843 1"/>
      </material>
    </collision>
  </link>
  <link name="track_mid_1">
    <visual>
      <origin rpy="0 0 0" xyz="0 0 0"/>
      <geometry>
        <mesh filename="package://abb_irbt4004/meshes/irbt4004/visual/Track_Mid.stl"/>
      </geometry>
      <material name="">
        <color rgba="0.7372549 0.3490196 0.1607843 1"/>
      </material>
    </visual>
    <collision>
      <origin rpy="0 0 0" xyz="0 0 0"/>
      <geometry>
        <mesh filename="package://abb_irbt4004/meshes/irbt4004/collision/Track_Mid.stl"/>
      </geometry>
      <material name="">
        <color rgba="0.7372549 0.3490196 0.1607843 1"/>
      </material>
    </collision>
  </link>
  <link name="track_mid_2">
    <visual>
      <origin rpy="0 0 0" xyz="0 0 0"/>
      <geometry>
        <mesh filename="package://abb_irbt4004/meshes/irbt4004/visual/Track_Mid.stl"/>
      </geometry>
      <material name="">
        <color rgba="0.7372549 0.3490196 0.1607843 1"/>
      </material>
    </visual>
    <collision>
      <origin rpy="0 0 0" xyz="0 0 0"/>
      <geometry>
        <mesh filename="package://abb_irbt4004/meshes/irbt4004/collision/Track_Mid.stl"/>
      </geometry>
      <material name="">
        <color rgba="0.7372549 0.3490196 0.1607843 1"/>
      </material>
    </collision>
  </link>
  <link name="track_mid_3">
    <visual>
      <origin rpy="0 0 0" xyz="0 0 0"/>
      <geometry>
        <mesh filename="package://abb_irbt4004/meshes/irbt4004/visual/Track_Mid.stl"/>
      </geometry>
      <material name="">
        <color rgba="0.7372549 0.3490196 0.1607843 1"/>
      </material>
    </visual>
    <collision>
      <origin rpy="0 0 0" xyz="0 0 0"/>
      <geometry>
        <mesh filename="package://abb_irbt4004/meshes/irbt4004/collision/Track_Mid.stl"/>
      </geometry>
      <material name="">
        <color rgba="0.7372549 0.3490196 0.1607843 1"/>
      </material>
    </collision>
  </link>
  <!-- no end section
    <link name="${prefix}track_end">
      <visual>
        <origin xyz="0 0 0" rpy="0 0 0"/>
        <geometry>
          <mesh filename="package://abb_irbt4004/meshes/irb4400/visual/Track_End.stl"/>
        </geometry>
        <xacro:material_abb_orange />
      </visual>
      <collision>
        <origin xyz="0 0 0" rpy="0 0 0"/>
        <geometry>
          <mesh filename="package://abb_irbt4004/meshes/irb4400/collision/Track_End.stl"/>
        </geometry>
        <xacro:material_abb_orange />
      </collision>
    </link>
    -->
  <link name="carriage">
    <visual>
      <origin rpy="0 0 0" xyz="0 0 0"/>
      <geometry>
        <mesh filename="package://abb_irbt4004/meshes/irbt4004/visual/Carriage_left.stl"/>
      </geometry>
      <material name="">
        <color rgba="0.3450980 0.3647059 0.3686275 1"/>
      </material>
    </visual>
    <collision>
      <origin rpy="0 0 0" xyz="0 0 0"/>
      <geometry>
        <mesh filename="package://abb_irbt4004/meshes/irbt4004/collision/Carriage_left.stl"/>
      </geometry>
      <material name="">
        <color rgba="0.3450980 0.3647059 0.3686275 1"/>
      </material>
    </collision>
  </link>
  <!-- end of link list -->
  <!-- joint list -->
  <joint name="fixed_track_mid_1" type="fixed">
    <parent link="base_link"/>
    <child link="track_mid_1"/>
    <origin rpy="0 0 0" xyz="0.000 0.000 0.000"/>
  </joint>
  <joint name="fixed_track_mid_2" type="fixed">
    <parent link="track_mid_1"/>
    <child link="track_mid_2"/>
    <origin rpy="0 0 0" xyz="1.000 0.000 0.000"/>
  </joint>
  <joint name="fixed_track_mid_3" type="fixed">
    <parent link="track_mid_2"/>
    <child link="track_mid_3"/>
    <origin rpy="0 0 0" xyz="1.000 0.000 0.000"/>
  </joint>
  <!-- no end section
    <joint name="${prefix}fixed_track_end" type="fixed">
      <parent link="${prefix}track_mid_3"/>
      <child link="${prefix}track_end"/>
      <origin xyz="1.000 0.000 0.000" rpy="0 0 0"/>
    </joint>
    -->
  <joint name="joint_carriage" type="prismatic">
    <parent link="base_link"/>
    <child link="carriage"/>
    <axis xyz="1 0 0"/>
    <limit effort="0" lower="0.000" upper="3.700" velocity="2.000"/>
    <!-- Product specification - IRBT 4004/6004/7004 -->
  </joint>
  <!-- offset to center base plate for robot mounting position
    <joint name="${prefix}fixed_base_link" type="fixed">
      <parent link="${prefix}carriage"/>
      <child link="${prefix}base_link"/>
      <origin xyz="0.3955 0.560 0.3745" rpy="0 0 1.57079632"/>
    </joint>-->
  <!-- end of joint list -->
  <!-- ROS base_link to ABB World Coordinates transform -->
  <link name="base"/>
  <joint name="base_link-base" type="fixed">
    <origin rpy="0 0 0" xyz="0 0 0"/>
    <parent link="base_link"/>
    <child link="base"/>
  </joint>
</robot>

